[2013-12-10 17:00:47,283 - autoapi running info]ERROR:ddd - runtest.py:12
[2013-12-16 15:03:03,428 - autoapi running info]WARNING:  sdfa? - mylog.py:14
2013-12-16 15:05:28,143 mylog.py[line:14] WARNING sdfa?
[2013-12-16 15:06:23,294 - autoapi running info]WARNING:  sdfa? - mylog.py:14
[2013-12-16 15:10:57,214 - autoapi running info]WARNING:  sdfa? - mylog.py:14
[2013-12-16 15:11:35,111 - autoapi running info]WARNING:  sdfa? - mylog.py:14
[2013-12-16 15:11:35,112 - autoapi running info]ERROR:  mismatched tag: line 3, column 19 - resolve_xml.py:95
[2013-12-16 15:13:06,674 - autoapi running info]WARNING:  sdfa? - mylog.py:14
[2013-12-16 15:13:06,676 - autoapi running info]ERROR:  mismatched tag: line 3, column 19 - resolve_xml.py:95
[2013-12-16 15:13:30,661 - autoapi running info]WARNING:  sdfa? - mylog.py:14
[2013-12-16 15:13:30,663 - autoapi running info]ERROR:  mismatched tag: line 3, column 19 - resolve_xml.py:95
[2013-12-16 15:34:08,569 - autoapi running info]WARNING:  sdfa? - mylog.py:14
[2013-12-16 15:35:20,829 - autoapi running info]WARNING:  sdfa? - mylog.py:14
[2013-12-16 15:36:12,938 - autoapi running info]WARNING:  sdfa? - mylog.py:14
[2013-12-16 15:36:12,940 - autoapi running info]ERROR:  mismatched tag: line 3, column 19 - resolve_xml.py:102
[2013-12-16 15:38:05,327 - autoapi running info]WARNING:  sdfa? - mylog.py:14
[2013-12-16 15:38:05,329 - autoapi running info]ERROR:  mismatched tag: line 3, column 19 - resolve_xml.py:102
[2013-12-16 15:39:47,581 - autoapi running info]WARNING:  sdfa? - mylog.py:14
[2013-12-16 15:40:05,001 - autoapi running info]WARNING:  sdfa? - mylog.py:14
[2013-12-16 15:40:05,003 - autoapi running info]ERROR:  mismatched tag: line 3, column 18 - resolve_xml.py:102
[2013-12-16 15:42:17,050 - autoapi running info]WARNING:  sdfa? - mylog.py:14
[2013-12-16 17:01:58,254 - autoapi error info]ERROR:  list index out of range - runtest.py:50
[2013-12-16 17:03:06,594 - autoapi error info]ERROR:  no test plan param. - runtest.py:50
[2013-12-16 17:09:09,669 - autoapi error info]ERROR:  [Errno 2] No such file or directory: u'queryid.api.xml' - resolve_xml.py:95
[2013-12-16 17:09:25,312 - autoapi error info]ERROR:  [Errno 2] No such file or directory: u'queryid.api.xml' - resolve_xml.py:95
[2013-12-16 17:09:25,313 - autoapi error info]ERROR:  list index out of range - resolve_xml.py:95
[2013-12-16 17:11:20,415 - autoapi error info]ERROR:  [Errno 2] No such file or directory: u'queryid.api.xml' - resolve_xml.py:95
[2013-12-16 17:11:20,416 - autoapi error info]ERROR:  list index out of range - resolve_xml.py:95
[2013-12-16 17:12:10,608 - autoapi error info]ERROR:  [Errno 2] No such file or directory: u'queryid.api.xml' - resolve_xml.py:95
[2013-12-16 17:12:10,609 - autoapi error info]ERROR:  list index out of range - resolve_xml.py:95
[2013-12-16 17:12:35,731 - autoapi error info]ERROR:  [Errno 2] No such file or directory: u'queryid.api.xml' - resolve_xml.py:95
[2013-12-16 17:12:35,732 - autoapi error info]ERROR:  list index out of range - resolve_xml.py:95
[2013-12-16 17:13:12,759 - autoapi error info]ERROR:  [Errno 2] No such file or directory: u'queryid.api.xml' - resolve_xml.py:95
[2013-12-16 17:13:12,760 - autoapi error info]ERROR:  list index out of range - resolve_xml.py:95
[2013-12-17 00:23:01,547 - autoapi error info]ERROR:  no test plan param. - runtest.py:50
[2013-12-17 11:48:54,638 - autoapi error info]ERROR:  no test plan param. - runtest.py:50
[2013-12-17 11:49:42,981 - autoapi error info]ERROR:  no test plan param. - runtest.py:50
[2013-12-17 13:01:26,571 - autoapi error info]ERROR:  [Errno 2] No such file or directory: u'queryid.api.xml' - resolve_xml.py:95
[2013-12-17 13:01:26,571 - autoapi error info]ERROR:  [Errno 2] No such file or directory: u'queryid.case.xml' - resolve_xml.py:95
[2013-12-17 13:02:36,217 - autoapi error info]ERROR:  [Errno 2] No such file or directory: u'queryid.api.xml' - resolve_xml.py:95
[2013-12-17 13:02:36,217 - autoapi error info]ERROR:  [Errno 2] No such file or directory: u'queryid.case.xml' - resolve_xml.py:95
[2013-12-17 14:50:41,872 - autoapi error info]ERROR:  'NodeList' object has no attribute 'getAttribute' - resolve_xml.py:97
[2013-12-18 14:16:49,237 - autoapi error info]ERROR:  'NodeList' object has no attribute 'getAttribute' - resolve_xml.py:99
[2013-12-18 14:33:47,757 - autoapi error info]ERROR:  'NodeList' object has no attribute 'getAttribute' - resolve_xml.py:99
[2013-12-18 17:15:14,875 - autoapi error info]ERROR:  no test plan param. - run.py:58
[2013-12-18 17:15:36,238 - autoapi error info]ERROR:  'NodeList' object has no attribute 'getAttribute' - resolve_xml.py:99
[2013-12-19 11:38:31,028 - autoapi error info]ERROR:  'NodeList' object has no attribute 'getAttribute' - resolve_xml.py:99
[2013-12-19 11:39:29,115 - autoapi error info]ERROR:  'NodeList' object has no attribute 'getAttribute' - resolve_xml.py:99
[2013-12-19 11:40:54,139 - autoapi error info]ERROR:  'NodeList' object has no attribute 'getAttribute' - resolve_xml.py:99
[2013-12-19 15:41:37,329 - autoapi error info]ERROR:  caldjaflsdjafljdslfjqla - mylog.py:12
[2013-12-19 17:03:10,279 - autoapi error info]ERROR:  rinimagebi - a.py:5
[2013-12-19 17:16:45,717 - autoapi error info]ERROR:  rinimagebi - a.py:5
[2013-12-19 19:04:18,010 - autoapi error info]ERROR:  rinima !!!!!!!!!!!!!!!!! - justtest.py:12
[2013-12-19 19:04:47,169 - autoapi error info]ERROR:  'NodeList' object has no attribute 'getAttribute' - resolve_xml.py:110
[2013-12-19 22:54:31,740 - autoapi error info]ERROR:  rinima !!!!!!!!!!!!!!!!! - justtest.py:12
[2013-12-19 23:12:29,235 - autoapi error info]ERROR:  'NodeList' object has no attribute 'getAttribute' - resolve_xml.py:105
[2013-12-19 23:16:48,408 - autoapi error info]ERROR:  'NodeList' object has no attribute 'getAttribute' - resolve_xml.py:105
[2013-12-19 23:17:40,297 - autoapi error info]ERROR:  'NodeList' object has no attribute 'getAttribute' - resolve_xml.py:106
[2013-12-19 23:18:10,440 - autoapi error info]ERROR:  'NodeList' object has no attribute 'getAttribute' - resolve_xml.py:107
[2013-12-19 23:18:30,456 - autoapi error info]ERROR:  'NodeList' object has no attribute 'getAttribute' - resolve_xml.py:108
[2013-12-19 23:19:28,631 - autoapi error info]ERROR:  'NodeList' object has no attribute 'getAttribute' - resolve_xml.py:108
[2013-12-19 23:19:47,352 - autoapi error info]ERROR:  'NodeList' object has no attribute 'getAttribute' - resolve_xml.py:109
[2013-12-19 23:20:14,561 - autoapi error info]ERROR:  global name 'case_wishr' is not defined - resolve_xml.py:110
[2013-12-19 23:21:02,265 - autoapi error info]ERROR:  global name 'case_wishr' is not defined - resolve_xml.py:111
[2013-12-19 23:21:13,265 - autoapi error info]ERROR:  'NodeList' object has no attribute 'getAttribute' - resolve_xml.py:111
[2013-12-19 23:21:38,257 - autoapi error info]ERROR:  'NodeList' object has no attribute 'getAttribute' - resolve_xml.py:112
[2013-12-19 23:21:57,689 - autoapi error info]ERROR:  'NodeList' object has no attribute 'getAttribute' - resolve_xml.py:110
[2013-12-19 23:22:29,561 - autoapi error info]ERROR:  'NodeList' object has no attribute 'getAttribute' - resolve_xml.py:111
[2013-12-19 23:23:14,008 - autoapi error info]ERROR:  'NodeList' object has no attribute 'getAttribute' - resolve_xml.py:112
[2013-12-20 11:43:06,473 - autoapi error info]ERROR:  not well-formed (invalid token): line 8, column 866 - resolve_xml.py:103
[2013-12-20 11:43:20,601 - autoapi error info]ERROR:  not well-formed (invalid token): line 8, column 866 - resolve_xml.py:104
[2013-12-20 11:44:06,417 - autoapi error info]ERROR:  not well-formed (invalid token): line 8, column 866 - resolve_xml.py:105
[2013-12-20 11:44:24,705 - autoapi error info]ERROR:  not well-formed (invalid token): line 8, column 866 - resolve_xml.py:105
[2013-12-20 11:45:36,291 - autoapi error info]ERROR:  not well-formed (invalid token): line 8, column 866 - resolve_xml.py:106
[2013-12-20 11:47:44,786 - autoapi error info]ERROR:  not well-formed (invalid token): line 9, column 828 - resolve_xml.py:106
[2013-12-20 11:58:55,279 - autoapi error info]ERROR:  not well-formed (invalid token): line 8, column 858 - resolve_xml.py:106
[2013-12-23 15:41:10,380 - autoapi error info]ERROR:  list indices must be integers, not str - resolve_xml.py:109
[2013-12-23 15:41:22,451 - autoapi error info]ERROR:  list indices must be integers, not str - resolve_xml.py:109
[2013-12-23 15:43:28,732 - autoapi error info]ERROR:  list indices must be integers, not str - resolve_xml.py:109
[2013-12-23 15:47:17,020 - autoapi error info]ERROR:  global name 'deal_json' is not defined - resolve_xml.py:105
[2013-12-23 15:47:37,708 - autoapi error info]ERROR:  global name 'deal_json' is not defined - resolve_xml.py:105
[2013-12-23 15:47:58,692 - autoapi error info]ERROR:  global name 'deal_json' is not defined - resolve_xml.py:106
[2013-12-23 15:48:30,924 - autoapi error info]ERROR:  global name 'json_obj' is not defined - resolve_xml.py:106
[2013-12-23 15:49:02,764 - autoapi error info]ERROR:  global name 'json_obj' is not defined - resolve_xml.py:105
[2013-12-23 15:50:04,681 - autoapi error info]ERROR:  string indices must be integers - resolve_xml.py:105
[2013-12-23 15:53:24,808 - autoapi error info]ERROR:  string indices must be integers - resolve_xml.py:105
[2013-12-23 15:54:02,864 - autoapi error info]ERROR:  string indices must be integers, not str - resolve_xml.py:105
[2013-12-23 15:54:50,169 - autoapi error info]ERROR:  string indices must be integers, not str - resolve_xml.py:105
[2013-12-24 16:35:35,169 - autoapi error info]ERROR:  list indices must be integers, not str - resolve_xml.py:105
[2013-12-24 16:35:46,969 - autoapi error info]ERROR:  list indices must be integers, not str - resolve_xml.py:105
[2013-12-24 16:40:50,250 - autoapi error info]ERROR:  list indices must be integers, not str - resolve_xml.py:107
[2013-12-24 16:41:32,811 - autoapi error info]ERROR:  list indices must be integers, not str - resolve_xml.py:108
