[2014-01-03 14:43:41,000 - autoapi error info]ERROR:  [Errno 2] No such file or directory: 'queryid.case.xml' - resolve_xml.py:132
[2014-01-03 14:55:23,917 - autoapi error info]ERROR:  [Errno 2] No such file or directory: 'query.api.xml' - resolve_xml.py:132
[2014-01-03 14:55:23,917 - autoapi error info]ERROR:  [Errno 2] No such file or directory: 'query.case.xml' - resolve_xml.py:132
[2014-01-03 14:56:14,616 - autoapi error info]ERROR:  [Errno 2] No such file or directory: 'query.api.xml' - resolve_xml.py:131
[2014-01-03 14:56:14,616 - autoapi error info]ERROR:  [Errno 2] No such file or directory: 'query.case.xml' - resolve_xml.py:131
[2014-01-03 14:56:53,196 - autoapi error info]ERROR:  [Errno 2] No such file or directory: 'query.api.xml' - resolve_xml.py:131
[2014-01-03 14:56:53,196 - autoapi error info]ERROR:  [Errno 2] No such file or directory: 'query.case.xml' - resolve_xml.py:131
[2014-01-03 14:57:50,645 - autoapi error info]ERROR:  [Errno 2] No such file or directory: 'query.api.xml' - resolve_xml.py:131
[2014-01-03 14:57:50,646 - autoapi error info]ERROR:  [Errno 2] No such file or directory: 'query.case.xml' - resolve_xml.py:131
[2014-01-03 15:00:48,344 - autoapi error info]ERROR:  [Errno 2] No such file or directory: 'query.api.xml' - resolve_xml.py:131
[2014-01-03 15:00:48,344 - autoapi error info]ERROR:  [Errno 2] No such file or directory: 'query.case.xml' - resolve_xml.py:131
[2014-01-06 16:57:12,758 - autoapi error info]ERROR:  [Errno 2] No such file or directory: 'zeyang.plan.xm' - resolve_xml.py:131
[2014-01-10 11:51:55,075 - autoapi error info]ERROR:  list index out of range - resolve_xml.py:131
[2014-01-10 11:52:55,464 - autoapi error info]ERROR:  list index out of range - resolve_xml.py:131
[2014-01-10 11:53:56,825 - autoapi error info]ERROR:  list index out of range - resolve_xml.py:131
[2014-01-10 11:54:11,470 - autoapi error info]ERROR:  list index out of range - resolve_xml.py:131
[2014-01-10 11:54:31,933 - autoapi error info]ERROR:  list index out of range - resolve_xml.py:131
[2014-01-11 17:43:01,817 - autoapi error info]ERROR:  mismatched tag: line 21, column 3 - resolve_xml.py:131
[2014-01-14 11:11:04,406 - autoapi error info]ERROR:  mismatched tag: line 21, column 3 - resolve_xml.py:131
[2014-01-14 14:34:26,953 - autoapi error info]ERROR:  mismatched tag: line 21, column 3 - resolve_xml.py:131
[2014-01-14 14:36:15,843 - autoapi error info]ERROR:  mismatched tag: line 21, column 3 - resolve_xml.py:131
[2014-01-14 14:37:16,979 - autoapi error info]ERROR:  mismatched tag: line 21, column 3 - resolve_xml.py:131
[2014-01-14 14:38:16,730 - autoapi error info]ERROR:  Get expect value errro. - deal_string.py:24
[2014-01-14 14:38:28,182 - autoapi error info]ERROR:  list index out of range - run.py:104
[2014-01-14 14:38:33,160 - autoapi error info]ERROR:  Get expect value errro. - deal_string.py:24
[2014-01-14 14:39:00,739 - autoapi error info]ERROR:  Get expect value errro. - deal_string.py:24
[2014-01-14 16:09:05,845 - autoapi error info]ERROR:  Get expect value errro. - deal_string.py:24
[2014-01-14 16:10:43,201 - autoapi error info]ERROR:  Get expect value errro. - deal_string.py:24
[2014-01-14 16:30:19,544 - autoapi error info]ERROR:  name 'false' is not defined - resolve_xml.py:131
[2014-01-14 16:31:24,881 - autoapi error info]ERROR:  name 'false' is not defined - resolve_xml.py:131
[2014-01-14 16:32:49,117 - autoapi error info]ERROR:  name 'false' is not defined - resolve_xml.py:131
[2014-01-14 16:36:22,035 - autoapi error info]ERROR:  name 'false' is not defined - resolve_xml.py:132
[2014-01-14 16:36:58,487 - autoapi error info]ERROR:  name 'false' is not defined - resolve_xml.py:134
[2014-01-14 16:39:24,784 - autoapi error info]ERROR:  name 'false' is not defined - resolve_xml.py:134
[2014-01-14 16:45:15,484 - autoapi error info]ERROR:  name 'false' is not defined - resolve_xml.py:134
[2014-01-14 16:45:34,877 - autoapi error info]ERROR:  name 'false' is not defined - resolve_xml.py:131
[2014-01-14 16:46:02,847 - autoapi error info]ERROR:  name 'false' is not defined - resolve_xml.py:132
[2014-01-14 16:48:02,635 - autoapi error info]ERROR:  name 'false' is not defined - resolve_xml.py:132
[2014-01-14 16:48:25,413 - autoapi error info]ERROR:  name 'false' is not defined - resolve_xml.py:132
[2014-01-14 17:23:55,044 - autoapi error info]ERROR:  name 'false' is not defined - resolve_xml.py:132
